<sdf version='1.4'>
  <model name='test_icub'>
    <link name='root_link'>
      <pose>0 0 0 0 -0 0</pose>
      <inertial>
        <pose>0 0 0 0 -0 0</pose>
        <mass>1.2</mass>
        <inertia>
          <ixx>0.01</ixx>
          <ixy>0</ixy>
          <ixz>0</ixz>
          <iyy>0.01</iyy>
          <iyz>0</iyz>
          <izz>0.01</izz>
        </inertia>
      </inertial>
      <collision name='root_link_collision'>
        <pose>0 0 0 0 -0 0</pose>
        <geometry>
          <mesh>
            <scale>1 1 1</scale>
            <uri>model://iCubGenova01/meshes/collision/icub_simple_collision_root_link.dae</uri>
          </mesh>
        </geometry>
      </collision>
      <visual name='root_link_visual'>
        <pose>0 0 0 0 -0 0</pose>
        <geometry>
          <mesh>
            <scale>1 1 1</scale>
            <uri>model://iCubGenova01/meshes/visual/icub_root_link.dae</uri>
          </mesh>
        </geometry>
      </visual>
      <velocity_decay>
        <linear>0</linear>
        <angular>0</angular>
      </velocity_decay>
    </link>
    <link name='l_hip_1'>
      <pose>0 -0.0681 -0.1199 2.65359e-06 1.57079 3.14159</pose>
      <inertial>
        <pose>8.0431e-05 -0.00691643 -0.0023047 0 -0 0</pose>
        <mass>0.695</mass>
        <inertia>
          <ixx>0.01</ixx>
          <ixy>-2.2209e-05</ixy>
          <ixz>1.39712e-05</ixz>
          <iyy>0.01</iyy>
          <iyz>4.77629e-05</iyz>
          <izz>0.01</izz>
        </inertia>
      </inertial>
      <collision name='l_hip_1_collision'>
        <pose>0 0 0 -0.785403 1.57079 -2.35619</pose>
        <geometry>
          <mesh>
            <scale>1 1 1</scale>
            <uri>model://iCubGenova01/meshes/collision/icub_simple_collision_l_hip_1.dae</uri>
          </mesh>
        </geometry>
      </collision>
      <visual name='l_hip_1_visual'>
        <pose>0 0 0 -0.785403 1.57079 -2.35619</pose>
        <geometry>
          <mesh>
            <scale>1 1 1</scale>
            <uri>model://iCubGenova01/meshes/visual/icub_l_hip_1.dae</uri>
          </mesh>
        </geometry>
      </visual>
      <velocity_decay>
        <linear>0</linear>
        <angular>0</angular>
      </velocity_decay>
    </link>
    <joint name='l_hip_pitch' type='revolute'>
      <child>l_hip_1</child>
      <parent>root_link</parent>
      <axis>
        <xyz>2.65359e-06 1 -9.74718e-12</xyz>
        <limit>
          <lower>-0.767945</lower>
          <upper>2.30383</upper>
          <effort>84</effort>
          <velocity>100</velocity>
        </limit>
        <dynamics/>
      </axis>
    </joint>
    <link name='l_hip_2'>
      <pose>0 -0.0681 -0.1199 3.14159 -7.34641e-06 3.14159</pose>
      <inertial>
        <pose>0.0010964 -3.13229e-05 0.0598624 0 -0 0</pose>
        <mass>0.982</mass>
        <inertia>
          <ixx>0.0253646</ixx>
          <ixy>1.2116e-06</ixy>
          <ixz>0.000491081</ixz>
          <iyy>0.0272714</iyy>
          <iyz>1.15713e-05</iyz>
          <izz>0.01</izz>
        </inertia>
      </inertial>
      <collision name='l_hip_2_collision'>
        <pose>0 0 0 0.785363 -1.57079 2.35623</pose>
        <geometry>
          <mesh>
            <scale>1 1 1</scale>
            <uri>model://iCubGenova01/meshes/collision/icub_simple_collision_l_hip_2.dae</uri>
          </mesh>
        </geometry>
      </collision>
      <visual name='l_hip_2_visual'>
        <pose>0 0 0 0.785363 -1.57079 2.35623</pose>
        <geometry>
          <mesh>
            <scale>1 1 1</scale>
            <uri>model://iCubGenova01/meshes/visual/icub_l_hip_2.dae</uri>
          </mesh>
        </geometry>
      </visual>
      <velocity_decay>
        <linear>0</linear>
        <angular>0</angular>
      </velocity_decay>
    </link>
    <joint name='l_hip_roll' type='revolute'>
      <child>l_hip_2</child>
      <parent>l_hip_1</parent>
      <axis>
        <xyz>-1 2.65359e-06 7.34641e-06</xyz>
        <limit>
          <lower>-2.07694</lower>
          <upper>0.296706</upper>
          <effort>84</effort>
          <velocity>100</velocity>
        </limit>
        <dynamics/>
      </axis>
    </joint>
    <link name='l_hip_3'>
      <pose>0 -0.0681 -0.1199 -9.99999e-06 2.65361e-06 -1.5708</pose>
      <inertial>
        <pose>0 0 0 0 -0 0</pose>
        <mass>0.1</mass>
        <inertia>
          <ixx>0.01</ixx>
          <ixy>0</ixy>
          <ixz>0</ixz>
          <iyy>0.01</iyy>
          <iyz>0</iyz>
          <izz>0.01</izz>
        </inertia>
      </inertial>
      <velocity_decay>
        <linear>0</linear>
        <angular>0</angular>
      </velocity_decay>
    </link>
    <joint name='l_leg_ft_sensor' type='revolute'>
      <child>l_hip_3</child>
      <parent>l_hip_2</parent>
      <axis>
        <xyz>0 0 0</xyz>
        <limit>
          <lower>0</lower>
          <upper>0</upper>
          <effort>0</effort>
          <velocity>0</velocity>
        </limit>
        <dynamics/>
      </axis>
      <sensor name='left_leg_ft' type='force_torque'>
        <always_on>1</always_on>
        <update_rate>100</update_rate>
        <pose>0 0 0 0 0 0</pose>
        <plugin name='left_leg_ft_plugin' filename='libgazebo_yarp_forcetorque.so'>
          <yarpConfigurationFile>model://iCubGenova01/conf/FT/gazebo_icub_left_leg_ft.ini</yarpConfigurationFile>
        </plugin>
      </sensor>
    </joint>
    <link name='l_thigh'>
      <pose>1.71821e-40 -0.0681 -0.1199 1.5708 -1e-05 3.14159</pose>
      <inertial>
        <pose>0.0021968 -0.174502 0.0013437 0 -0 0</pose>
        <mass>1.522</mass>
        <inertia>
          <ixx>0.0454917</ixx>
          <ixy>-0.000940971</ixy>
          <ixz>5.37405e-05</ixz>
          <iyy>0.01004</iyy>
          <iyz>0.001203</iyz>
          <izz>0.0458255</izz>
        </inertia>
      </inertial>
      <collision name='l_thigh_collision'>
        <pose>0 0 0 -2.67795 1.57079 -1.10714</pose>
        <geometry>
          <mesh>
            <scale>1 1 1</scale>
            <uri>model://iCubGenova01/meshes/collision/icub_simple_collision_l_thigh.dae</uri>
          </mesh>
        </geometry>
      </collision>
      <visual name='l_thigh_visual'>
        <pose>0 0 0 -2.67795 1.57079 -1.10714</pose>
        <geometry>
          <mesh>
            <scale>1 1 1</scale>
            <uri>model://iCubGenova01/meshes/visual/icub_l_thigh.dae</uri>
          </mesh>
        </geometry>
      </visual>
      <velocity_decay>
        <linear>0</linear>
        <angular>0</angular>
      </velocity_decay>
    </link>
    <joint name='l_hip_yaw' type='revolute'>
      <child>l_thigh</child>
      <parent>l_hip_3</parent>
      <axis>
        <xyz>1e-05 1.01961e-06 1</xyz>
        <limit>
          <lower>-1.37881</lower>
          <upper>1.37881</upper>
          <effort>40</effort>
          <velocity>100</velocity>
        </limit>
        <dynamics/>
      </axis>
    </joint>
    <link name='l_shank'>
      <pose>0.000915155 -0.0681002 -0.354445 1.49636 -1.57078 0.0744313</pose>
      <inertial>
        <pose>-0.0761044 -4.50091e-05 0.0062408 0 -0 0</pose>
        <mass>2.032</mass>
        <inertia>
          <ixx>0.0154559</ixx>
          <ixy>-0.0013903</ixy>
          <ixz>-0.0039454</ixz>
          <iyy>0.070277</iyy>
          <iyz>0.00071995</iyz>
          <izz>0.0659645</izz>
        </inertia>
      </inertial>
      <collision name='l_shank_collision'>
        <pose>0.010945 0.0009175 2.28224e-12 -3.14159 -7.26748e-17 1.5708</pose>
        <geometry>
          <mesh>
            <scale>1 1 1</scale>
            <uri>model://iCubGenova01/meshes/collision/icub_simple_collision_l_shank.dae</uri>
          </mesh>
        </geometry>
      </collision>
      <visual name='l_shank_visual'>
        <pose>0.010945 0.0009175 2.28224e-12 -3.14159 -7.26748e-17 1.5708</pose>
        <geometry>
          <mesh>
            <scale>1 1 1</scale>
            <uri>model://iCubGenova01/meshes/visual/icub_l_shank.dae</uri>
          </mesh>
        </geometry>
      </visual>
      <velocity_decay>
        <linear>0</linear>
        <angular>0</angular>
      </velocity_decay>
    </link>
    <joint name='l_knee' type='revolute'>
      <child>l_shank</child>
      <parent>l_thigh</parent>
      <axis>
        <xyz>5.30716e-06 1 -1.01967e-06</xyz>
        <limit>
          <lower>-2.18166</lower>
          <upper>0.401426</upper>
          <effort>30</effort>
          <velocity>100</velocity>
        </limit>
        <dynamics/>
      </axis>
    </joint>
    <link name='l_ankle_1'>
      <pose>0.000912413 -0.0681004 -0.554945 -0.0744403 -1.57078 0.0744313</pose>
      <inertial>
        <pose>2.65892e-05 -0.00082253 0.0102574 0 -0 0</pose>
        <mass>0.643</mass>
        <inertia>
          <ixx>4.76593</ixx>
          <ixy>9.7426e-06</ixy>
          <ixz>2.68085e-05</ixz>
          <iyy>0.01</iyy>
          <iyz>-0.000353796</iyz>
          <izz>0.01</izz>
        </inertia>
      </inertial>
      <collision name='l_ankle_1_collision'>
        <pose>-0.001555 -5.54333e-12 0.0009175 1.5708 1.53106e-11 1.53103e-11</pose>
        <geometry>
          <mesh>
            <scale>1 1 1</scale>
            <uri>model://iCubGenova01/meshes/collision/icub_simple_collision_l_ankle_1.dae</uri>
          </mesh>
        </geometry>
      </collision>
      <visual name='l_ankle_1_visual'>
        <pose>-0.001555 -5.54333e-12 0.0009175 1.5708 1.53106e-11 1.53103e-11</pose>
        <geometry>
          <mesh>
            <scale>1 1 1</scale>
            <uri>model://iCubGenova01/meshes/visual/icub_l_ankle_1.dae</uri>
          </mesh>
        </geometry>
      </visual>
      <velocity_decay>
        <linear>0</linear>
        <angular>0</angular>
      </velocity_decay>
    </link>
    <joint name='l_ankle_pitch' type='revolute'>
      <child>l_ankle_1</child>
      <parent>l_shank</parent>
      <axis>
        <xyz>-8.98037e-06 -1 1.01972e-06</xyz>
        <limit>
          <lower>-0.733038</lower>
          <upper>0.366519</upper>
          <effort>24</effort>
          <velocity>100</velocity>
        </limit>
        <dynamics/>
      </axis>
    </joint>
    <link name='l_upper_foot'>
      <pose>0.000912413 -0.0681004 -0.554945 -3.14159 -9.99999e-06 3.14158</pose>
      <inertial>
        <pose>-0.0035 0 -0.0065 0 -0 0</pose>
        <mass>0.1</mass>
        <inertia>
          <ixx>0.01</ixx>
          <ixy>0</ixy>
          <ixz>0</ixz>
          <iyy>0.01</iyy>
          <iyz>0</iyz>
          <izz>0.01</izz>
        </inertia>
      </inertial>
      <velocity_decay>
        <linear>0</linear>
        <angular>0</angular>
      </velocity_decay>
    </link>
    <joint name='l_ankle_roll' type='revolute'>
      <child>l_upper_foot</child>
      <parent>l_ankle_1</parent>
      <axis>
        <xyz>-1 8.98038e-06 9.99999e-06</xyz>
        <limit>
          <lower>-0.418879</lower>
          <upper>0.418879</upper>
          <effort>11</effort>
          <velocity>100</velocity>
        </limit>
        <dynamics/>
      </axis>
    </joint>
    <link name='l_foot'>
      <pose>0.00441173 -0.0681005 -0.623445 -0.0744403 -1.57078 0.0744313</pose>
      <inertial>
        <pose>-0.0425846 -0.000613931 0.024069 0 -0 0</pose>
        <mass>0.761</mass>
        <inertia>
          <ixx>0.01</ixx>
          <ixy>2.77674e-06</ixy>
          <ixz>-0.000650678</ixz>
          <iyy>0.01</iyy>
          <iyz>-4.51893e-06</iyz>
          <izz>0.01</izz>
        </inertia>
      </inertial>
      <collision name='l_foot_collision'>
        <pose>0.066945 -5.54332e-12 0.0044175 5.10331e-12 1.53106e-11 1.53103e-11</pose>
        <geometry>
          <mesh>
            <scale>1 1 1</scale>
            <uri>model://iCubGenova01/meshes/collision/icub_simple_collision_l_foot.dae</uri>
          </mesh>
        </geometry>
        <surface>
          <contact>
            <ode>
              <kp>1e06</kp>
              <kd>100</kd>
              <max_vel>1</max_vel>
              <min_depth>0</min_depth>
            </ode>
          </contact>
          <friction>
            <ode>
              <mu>1</mu>
              <mu2>1</mu2>
              <fdir1>1 0 0</fdir1>
            </ode>
          </friction>
        </surface>
      </collision>
      <visual name='l_foot_visual'>
        <pose>0.066945 -5.54332e-12 0.0044175 5.10331e-12 1.53106e-11 1.53103e-11</pose>
        <geometry>
          <mesh>
            <scale>1 1 1</scale>
            <uri>model://iCubGenova01/meshes/visual/icub_l_foot.dae</uri>
          </mesh>
        </geometry>
      </visual>
      <velocity_decay>
        <linear>0</linear>
        <angular>0</angular>
      </velocity_decay>
    </link>
    <joint name='l_foot_ft_sensor' type='revolute'>
      <child>l_foot</child>
      <parent>l_upper_foot</parent>
      <axis>
        <xyz>0 0 0</xyz>
        <limit>
          <lower>0</lower>
          <upper>0</upper>
          <effort>0</effort>
          <velocity>0</velocity>
        </limit>
        <dynamics/>
      </axis>
      <sensor name='left_foot_ft' type='force_torque'>
        <always_on>1</always_on>
        <update_rate>100</update_rate>
        <pose>0 0 0 0 0 0</pose>
        <plugin name='left_foot_ft_plugin' filename='libgazebo_yarp_forcetorque.so'>
          <yarpConfigurationFile>model://iCubGenova01/conf/FT/gazebo_icub_left_foot_ft.ini</yarpConfigurationFile>
        </plugin>
      </sensor>
    </joint>
    <link name='r_hip_1'>
      <pose>0 0.0681 -0.1199 3.14159 1.57079 -3.14159</pose>
      <inertial>
        <pose>8.0431e-05 -0.00691643 0.0023047 0 -0 0</pose>
        <mass>0.695</mass>
        <inertia>
          <ixx>0.01</ixx>
          <ixy>-2.2209e-05</ixy>
          <ixz>-1.39712e-05</ixz>
          <iyy>0.01</iyy>
          <iyz>-4.77629e-05</iyz>
          <izz>0.01</izz>
        </inertia>
      </inertial>
      <collision name='r_hip_1_collision'>
        <pose>0 0 0 1.76819 -1.57079 2.76109</pose>
        <geometry>
          <mesh>
            <scale>1 1 1</scale>
            <uri>model://iCubGenova01/meshes/collision/icub_simple_collision_r_hip_1.dae</uri>
          </mesh>
        </geometry>
      </collision>
      <visual name='r_hip_1_visual'>
        <pose>0 0 0 1.76819 -1.57079 2.76109</pose>
        <geometry>
          <mesh>
            <scale>1 1 1</scale>
            <uri>model://iCubGenova01/meshes/visual/icub_r_hip_1.dae</uri>
          </mesh>
        </geometry>
      </visual>
      <velocity_decay>
        <linear>0</linear>
        <angular>0</angular>
      </velocity_decay>
    </link>
    <joint name='r_hip_pitch' type='revolute'>
      <child>r_hip_1</child>
      <parent>root_link</parent>
      <axis>
        <xyz>5.7211e-18 1 -1.22967e-22</xyz>
        <limit>
          <lower>-0.767945</lower>
          <upper>2.30383</upper>
          <effort>84</effort>
          <velocity>100</velocity>
        </limit>
        <dynamics/>
      </axis>
    </joint>
    <link name='r_hip_2'>
      <pose>0 0.0681 -0.1199 -3.14159 -7.34641e-06 -3.14159</pose>
      <inertial>
        <pose>0.0010964 -3.13229e-05 0.0598624 0 -0 0</pose>
        <mass>0.982</mass>
        <inertia>
          <ixx>0.0253646</ixx>
          <ixy>1.2116e-06</ixy>
          <ixz>0.000491081</ixz>
          <iyy>0.0272714</iyy>
          <iyz>1.15713e-05</iyz>
          <izz>0.01</izz>
        </inertia>
      </inertial>
      <collision name='r_hip_2_collision'>
        <pose>0 0 0 -2.35627 -1.57079 2.35627</pose>
        <geometry>
          <mesh>
            <scale>1 1 1</scale>
            <uri>model://iCubGenova01/meshes/collision/icub_simple_collision_r_hip_2.dae</uri>
          </mesh>
        </geometry>
      </collision>
      <visual name='r_hip_2_visual'>
        <pose>0 0 0 -2.35627 -1.57079 2.35627</pose>
        <geometry>
          <mesh>
            <scale>1 1 1</scale>
            <uri>model://iCubGenova01/meshes/visual/icub_r_hip_2.dae</uri>
          </mesh>
        </geometry>
      </visual>
      <velocity_decay>
        <linear>0</linear>
        <angular>0</angular>
      </velocity_decay>
    </link>
    <joint name='r_hip_roll' type='revolute'>
      <child>r_hip_2</child>
      <parent>r_hip_1</parent>
      <axis>
        <xyz>1 5.55111e-17 -7.34641e-06</xyz>
        <limit>
          <lower>-2.07694</lower>
          <upper>0.296706</upper>
          <effort>84</effort>
          <velocity>100</velocity>
        </limit>
        <dynamics/>
      </axis>
    </joint>
    <link name='r_hip_3'>
      <pose>0 0.0681 -0.1199 -3.14159 2.69849e-11 1.57079</pose>
      <inertial>
        <pose>0 0 0 0 -0 0</pose>
        <mass>0.1</mass>
        <inertia>
          <ixx>0.01</ixx>
          <ixy>0</ixy>
          <ixz>0</ixz>
          <iyy>0.01</iyy>
          <iyz>0</iyz>
          <izz>0.01</izz>
        </inertia>
      </inertial>
      <velocity_decay>
        <linear>0</linear>
        <angular>0</angular>
      </velocity_decay>
    </link>
    <joint name='r_leg_ft_sensor' type='revolute'>
      <child>r_hip_3</child>
      <parent>r_hip_2</parent>
      <axis>
        <xyz>0 0 -0</xyz>
        <limit>
          <lower>0</lower>
          <upper>0</upper>
          <effort>0</effort>
          <velocity>0</velocity>
        </limit>
        <dynamics/>
      </axis>
      <sensor name='right_leg_ft' type='force_torque'>
        <always_on>1</always_on>
        <update_rate>100</update_rate>
        <pose>0 0 0 0 0 0</pose>
        <plugin name='right_leg_ft_plugin' filename='libgazebo_yarp_forcetorque.so'>
          <yarpConfigurationFile>model://iCubGenova01/conf/FT/gazebo_icub_right_leg_ft.ini</yarpConfigurationFile>
        </plugin>
      </sensor>
    </joint>
    <link name='r_thigh'>
      <pose>6.19005e-40 0.0681 -0.1199 1.57079 -7.34641e-06 3.14159</pose>
      <inertial>
        <pose>0.0021968 -0.174502 -0.0013437 0 -0 0</pose>
        <mass>1.522</mass>
        <inertia>
          <ixx>0.0454917</ixx>
          <ixy>-0.000940971</ixy>
          <ixz>-5.37405e-05</ixz>
          <iyy>0.01004</iyy>
          <iyz>-0.001203</iyz>
          <izz>0.0458255</izz>
        </inertia>
      </inertial>
      <collision name='r_thigh_collision'>
        <pose>0 0 0 1.57083 -1.57079 -3.26535e-05</pose>
        <geometry>
          <mesh>
            <scale>1 1 1</scale>
            <uri>model://iCubGenova01/meshes/collision/icub_simple_collision_r_thigh.dae</uri>
          </mesh>
        </geometry>
      </collision>
      <visual name='r_thigh_visual'>
        <pose>0 0 0 1.57083 -1.57079 -3.26535e-05</pose>
        <geometry>
          <mesh>
            <scale>1 1 1</scale>
            <uri>model://iCubGenova01/meshes/visual/icub_r_thigh.dae</uri>
          </mesh>
        </geometry>
      </visual>
      <velocity_decay>
        <linear>0</linear>
        <angular>0</angular>
      </velocity_decay>
    </link>
    <joint name='r_hip_yaw' type='revolute'>
      <child>r_thigh</child>
      <parent>r_hip_3</parent>
      <axis>
        <xyz>-7.34641e-06 3.67321e-06 -1</xyz>
        <limit>
          <lower>-1.37881</lower>
          <upper>1.37881</upper>
          <effort>40</effort>
          <velocity>100</velocity>
        </limit>
        <dynamics/>
      </axis>
    </joint>
    <link name='r_shank'>
      <pose>0.000915777 0.0681009 -0.354445 1.89254 -1.57078 -0.321751</pose>
      <inertial>
        <pose>-0.0761044 -4.50091e-05 -0.0062408 0 -0 0</pose>
        <mass>2.032</mass>
        <inertia>
          <ixx>0.0154559</ixx>
          <ixy>-0.0013903</ixy>
          <ixz>0.0039454</ixz>
          <iyy>0.070277</iyy>
          <iyz>-0.00071995</iyz>
          <izz>0.0659645</izz>
        </inertia>
      </inertial>
      <collision name='r_shank_collision'>
        <pose>0.010945 0.0009175 -2.77556e-17 3.14159 2.71835e-16 1.5708</pose>
        <geometry>
          <mesh>
            <scale>1 1 1</scale>
            <uri>model://iCubGenova01/meshes/collision/icub_simple_collision_r_shank.dae</uri>
          </mesh>
        </geometry>
      </collision>
      <visual name='r_shank_visual'>
        <pose>0.010945 0.0009175 -2.77556e-17 3.14159 2.71835e-16 1.5708</pose>
        <geometry>
          <mesh>
            <scale>1 1 1</scale>
            <uri>model://iCubGenova01/meshes/visual/icub_r_shank.dae</uri>
          </mesh>
        </geometry>
      </visual>
      <velocity_decay>
        <linear>0</linear>
        <angular>0</angular>
      </velocity_decay>
    </link>
    <joint name='r_knee' type='revolute'>
      <child>r_shank</child>
      <parent>r_thigh</parent>
      <axis>
        <xyz>2.65362e-06 1 3.67318e-06</xyz>
        <limit>
          <lower>-2.18166</lower>
          <upper>0.401426</upper>
          <effort>30</effort>
          <velocity>100</velocity>
        </limit>
        <dynamics/>
      </axis>
    </joint>
    <link name='r_ankle_1'>
      <pose>0.000913568 0.0681016 -0.554945 -2.81984 -1.57078 -0.321751</pose>
      <inertial>
        <pose>-2.65892e-05 -0.00082253 -0.0102574 0 -0 0</pose>
        <mass>0.643</mass>
        <inertia>
          <ixx>4.76593</ixx>
          <ixy>9.7426e-06</ixy>
          <ixz>-2.68085e-05</ixz>
          <iyy>0.01</iyy>
          <iyz>0.000353796</iyz>
          <izz>0.01</izz>
        </inertia>
      </inertial>
      <collision name='r_ankle_1_collision'>
        <pose>-0.001555 -1.08707e-12 -0.0009175 -1.5708 -1.53106e-11 5.10353e-12</pose>
        <geometry>
          <mesh>
            <scale>1 1 1</scale>
            <uri>model://iCubGenova01/meshes/collision/icub_simple_collision_r_ankle_1.dae</uri>
          </mesh>
        </geometry>
      </collision>
      <visual name='r_ankle_1_visual'>
        <pose>-0.001555 -1.08707e-12 -0.0009175 -1.5708 -1.53106e-11 5.10353e-12</pose>
        <geometry>
          <mesh>
            <scale>1 1 1</scale>
            <uri>model://iCubGenova01/meshes/visual/icub_r_ankle_1.dae</uri>
          </mesh>
        </geometry>
      </visual>
      <velocity_decay>
        <linear>0</linear>
        <angular>0</angular>
      </velocity_decay>
    </link>
    <joint name='r_ankle_pitch' type='revolute'>
      <child>r_ankle_1</child>
      <parent>r_shank</parent>
      <axis>
        <xyz>1.01959e-06 -1 -3.67322e-06</xyz>
        <limit>
          <lower>-0.733038</lower>
          <upper>0.366519</upper>
          <effort>24</effort>
          <velocity>100</velocity>
        </limit>
        <dynamics/>
      </axis>
    </joint>
    <link name='r_upper_foot'>
      <pose>0.000913568 0.0681016 -0.554945 3.14159 -1.4236e-05 -3.14159</pose>
      <inertial>
        <pose>-0.0035 4.28626e-19 -0.0065 0 -0 0</pose>
        <mass>0.1</mass>
        <inertia>
          <ixx>0.01</ixx>
          <ixy>-2.35099e-38</ixy>
          <ixz>0</ixz>
          <iyy>0.01</iyy>
          <iyz>4.70198e-38</iyz>
          <izz>0.01</izz>
        </inertia>
      </inertial>
      <velocity_decay>
        <linear>0</linear>
        <angular>0</angular>
      </velocity_decay>
    </link>
    <joint name='r_ankle_roll' type='revolute'>
      <child>r_upper_foot</child>
      <parent>r_ankle_1</parent>
      <axis>
        <xyz>1 2.79362e-06 -1.4236e-05</xyz>
        <limit>
          <lower>-0.418879</lower>
          <upper>0.418879</upper>
          <effort>11</effort>
          <velocity>100</velocity>
        </limit>
        <dynamics/>
      </axis>
    </joint>
    <link name='r_foot'>
      <pose>0.00441259 0.0681021 -0.623445 0.388334 -1.57078 -0.388331</pose>
      <inertial>
        <pose>-0.0425846 0.000613931 0.024069 0 -0 0</pose>
        <mass>0.761</mass>
        <inertia>
          <ixx>0.01</ixx>
          <ixy>-2.77691e-06</ixy>
          <ixz>-0.000650678</ixz>
          <iyy>0.01</iyy>
          <iyz>4.51893e-06</iyz>
          <izz>0.01</izz>
        </inertia>
      </inertial>
      <collision name='r_foot_collision'>
        <pose>0.066945 1.08706e-12 0.0044175 -3.14159 1.53111e-11 -5.10353e-12</pose>
        <geometry>
          <mesh>
            <scale>1 1 1</scale>
            <uri>model://iCubGenova01/meshes/collision/icub_simple_collision_r_foot.dae</uri>
          </mesh>
        </geometry>
        <surface>
          <contact>
            <ode>
              <kp>1e06</kp>
              <kd>100</kd>
              <max_vel>1</max_vel>
              <min_depth>0</min_depth>
            </ode>
          </contact>
          <friction>
            <ode>
              <mu>1</mu>
              <mu2>1</mu2>
              <fdir1>1 0 0</fdir1>
            </ode>
          </friction>
        </surface>
      </collision>
      <visual name='r_foot_visual'>
        <pose>0.066945 1.08706e-12 0.0044175 -3.14159 1.53111e-11 -5.10353e-12</pose>
        <geometry>
          <mesh>
            <scale>1 1 1</scale>
            <uri>model://iCubGenova01/meshes/visual/icub_r_foot.dae</uri>
          </mesh>
        </geometry>
      </visual>
      <velocity_decay>
        <linear>0</linear>
        <angular>0</angular>
      </velocity_decay>
    </link>
    <joint name='r_foot_ft_sensor' type='revolute'>
      <child>r_foot</child>
      <parent>r_upper_foot</parent>
      <axis>
        <xyz>0 0 0</xyz>
        <limit>
          <lower>0</lower>
          <upper>0</upper>
          <effort>0</effort>
          <velocity>0</velocity>
        </limit>
        <dynamics/>
      </axis>
      <sensor name='right_foot_ft' type='force_torque'>
        <always_on>1</always_on>
        <update_rate>100</update_rate>
        <pose>0 0 0 0 0 0</pose>
        <plugin name='right_foot_ft_plugin' filename='libgazebo_yarp_forcetorque.so'>
          <yarpConfigurationFile>model://iCubGenova01/conf/FT/gazebo_icub_right_foot_ft.ini</yarpConfigurationFile>
        </plugin>
      </sensor>
    </joint>
    <link name='lap_belt_1'>
      <pose>0 0 0 3.14159 -1.57079 -2.65359e-06</pose>
      <inertial>
        <pose>0 0 0 0 -0 0</pose>
        <mass>0.1</mass>
        <inertia>
          <ixx>0.01</ixx>
          <ixy>-4.263e-05</ixy>
          <ixz>-3.889e-08</ixz>
          <iyy>0.01</iyy>
          <iyz>0</iyz>
          <izz>0.01</izz>
        </inertia>
      </inertial>
      <collision name='lap_belt_1_collision'>
        <pose>0 0 0 -1.5708 5.10314e-12 1.11022e-16</pose>
        <geometry>
          <mesh>
            <scale>1 1 1</scale>
            <uri>model://iCubGenova01/meshes/collision/icub_simple_collision_lap_belt_1.dae</uri>
          </mesh>
        </geometry>
      </collision>
      <visual name='lap_belt_1_visual'>
        <pose>0 0 0 -1.5708 5.10314e-12 1.11022e-16</pose>
        <geometry>
          <mesh>
            <scale>1 1 1</scale>
            <uri>model://iCubGenova01/meshes/visual/icub_lap_belt_1.dae</uri>
          </mesh>
        </geometry>
      </visual>
      <velocity_decay>
        <linear>0</linear>
        <angular>0</angular>
      </velocity_decay>
    </link>
    <joint name='torso_pitch' type='revolute'>
      <child>lap_belt_1</child>
      <parent>root_link</parent>
      <axis>
        <xyz>-2.65359e-06 -1 -1.05879e-22</xyz>
        <limit>
          <lower>-0.383972</lower>
          <upper>1.46608</upper>
          <effort>36</effort>
          <velocity>100</velocity>
        </limit>
        <dynamics/>
      </axis>
    </joint>
    <link name='lap_belt_2'>
      <pose>1.17543e-07 -3.1191e-13 0.032 -3.14159 3.67321e-06 1.57079</pose>
      <inertial>
        <pose>0 0 0 0 -0 0</pose>
        <mass>0.1</mass>
        <inertia>
          <ixx>0.01</ixx>
          <ixy>-1.923e-06</ixy>
          <ixz>5.095e-05</ixz>
          <iyy>0.01</iyy>
          <iyz>-3.849e-07</iyz>
          <izz>0.01</izz>
        </inertia>
      </inertial>
      <velocity_decay>
        <linear>0</linear>
        <angular>0</angular>
      </velocity_decay>
    </link>
    <joint name='torso_roll' type='revolute'>
      <child>lap_belt_2</child>
      <parent>lap_belt_1</parent>
      <axis>
        <xyz>1 -2.6536e-06 -7.34641e-06</xyz>
        <limit>
          <lower>-0.680678</lower>
          <upper>0.680678</upper>
          <effort>80</effort>
          <velocity>100</velocity>
        </limit>
        <dynamics/>
      </axis>
    </joint>
    <link name='chest'>
      <pose>-0.00549988 1.45945e-08 0.032 1.5708 -7.34642e-06 -3.14159</pose>
      <inertial>
        <pose>0.00222898 0.075 -1.18362e-17 0 -0 0</pose>
        <mass>4.81</mass>
        <inertia>
          <ixx>0.07472</ixx>
          <ixy>-3.6e-06</ixy>
          <ixz>-4.705e-05</ixz>
          <iyy>0.08145</iyy>
          <iyz>0.004567</iyz>
          <izz>0.01306</izz>
        </inertia>
      </inertial>
      <collision name='chest_collision'>
        <pose>-0.0055 -6.93889e-18 -3.55271e-18 -1.10717 -1.57079 2.67798</pose>
        <geometry>
          <mesh>
            <scale>1 1 1</scale>
            <uri>model://iCubGenova01/meshes/collision/icub_simple_collision_chest.dae</uri>
          </mesh>
        </geometry>
      </collision>
      <visual name='chest_visual'>
        <pose>-0.0055 -6.93889e-18 -3.55271e-18 -1.10717 -1.57079 2.67798</pose>
        <geometry>
          <mesh>
            <scale>1 1 1</scale>
            <uri>model://iCubGenova01/meshes/visual/icub_chest.dae</uri>
          </mesh>
        </geometry>
      </visual>
      <velocity_decay>
        <linear>0</linear>
        <angular>0</angular>
      </velocity_decay>
    </link>
    <joint name='torso_yaw' type='revolute'>
      <child>chest</child>
      <parent>lap_belt_2</parent>
      <axis>
        <xyz>-7.34642e-06 1.94942e-11 -1</xyz>
        <limit>
          <lower>-1.02974</lower>
          <upper>1.02974</upper>
          <effort>80</effort>
          <velocity>100</velocity>
        </limit>
        <dynamics/>
      </axis>
    </joint>
    <link name='l_shoulder_1'>
      <pose>-0.0107487 -0.11026 0.1753 -0.261794 -1.57079 -1.42917e-06</pose>
      <inertial>
        <pose>-5e-06 0.0187 -0.00119 0 -0 0</pose>
        <mass>0.189</mass>
        <inertia>
          <ixx>0.01</ixx>
          <ixy>9e-09</ixy>
          <ixz>0</ixz>
          <iyy>0.01</iyy>
          <iyz>-1.7e-08</iyz>
          <izz>0.01</izz>
        </inertia>
      </inertial>
      <collision name='l_shoulder_1_collision'>
        <pose>3.08642e-14 0.109285 -0.00521101 -0.301063 1.57079 -1.87186</pose>
        <geometry>
          <mesh>
            <scale>1 1 1</scale>
            <uri>model://iCubGenova01/meshes/collision/icub_simple_collision_l_shoulder_1.dae</uri>
          </mesh>
        </geometry>
      </collision>
      <visual name='l_shoulder_1_visual'>
        <pose>3.08642e-14 0.109285 -0.00521101 -0.301063 1.57079 -1.87186</pose>
        <geometry>
          <mesh>
            <scale>1 1 1</scale>
            <uri>model://iCubGenova01/meshes/visual/icub_l_shoulder_1.dae</uri>
          </mesh>
        </geometry>
      </visual>
      <velocity_decay>
        <linear>0</linear>
        <angular>0</angular>
      </velocity_decay>
    </link>
    <joint name='l_shoulder_pitch' type='revolute'>
      <child>l_shoulder_1</child>
      <parent>chest</parent>
      <axis>
        <xyz>-0.258815 -0.965927 2.85203e-06</xyz>
        <limit>
          <lower>-1.65806</lower>
          <upper>0.0872665</upper>
          <effort>84</effort>
          <velocity>100</velocity>
        </limit>
        <dynamics/>
      </axis>
    </joint>
    <link name='l_shoulder_2'>
      <pose>-0.0107487 -0.11026 0.1753 3.14159 8.21174e-07 -1.83259</pose>
      <inertial>
        <pose>9.4e-05 -0.00627 0.0166 0 -0 0</pose>
        <mass>0.179</mass>
        <inertia>
          <ixx>0.01</ixx>
          <ixy>4.66e-07</ixy>
          <ixz>3.65e-07</ixz>
          <iyy>0.01</iyy>
          <iyz>-2.0524e-05</iyz>
          <izz>0.01</izz>
        </inertia>
      </inertial>
      <collision name='l_shoulder_2_collision'>
        <pose>-0.00154529 -0.00521101 -1.11181e-12 -2.14033 1.57079 -0.569533</pose>
        <geometry>
          <mesh>
            <scale>1 1 1</scale>
            <uri>model://iCubGenova01/meshes/collision/icub_simple_collision_l_shoulder_2.dae</uri>
          </mesh>
        </geometry>
      </collision>
      <visual name='l_shoulder_2_visual'>
        <pose>-0.00154529 -0.00521101 -1.11181e-12 -2.14033 1.57079 -0.569533</pose>
        <geometry>
          <mesh>
            <scale>1 1 1</scale>
            <uri>model://iCubGenova01/meshes/visual/icub_l_shoulder_2.dae</uri>
          </mesh>
        </geometry>
      </visual>
      <velocity_decay>
        <linear>0</linear>
        <angular>0</angular>
      </velocity_decay>
    </link>
    <joint name='l_shoulder_roll' type='revolute'>
      <child>l_shoulder_2</child>
      <parent>l_shoulder_1</parent>
      <axis>
        <xyz>-0.965927 0.258815 6.97095e-06</xyz>
        <limit>
          <lower>0</lower>
          <upper>2.80649</upper>
          <effort>84</effort>
          <velocity>100</velocity>
        </limit>
        <dynamics/>
      </axis>
    </joint>
    <link name='l_upper_arm'>
      <pose>-0.0107487 -0.11026 0.1753 3.14159 -6.5209e-06 -3.14159</pose>
      <inertial>
        <pose>0.00559398 9.77357e-05 0.0501346 0 -0 0</pose>
        <mass>0.156157</mass>
        <inertia>
          <ixx>0.01</ixx>
          <ixy>-5.662e-08</ixy>
          <ixz>-4.3618e-06</ixz>
          <iyy>0.01</iyy>
          <iyz>-7.42844e-07</iyz>
          <izz>0.01</izz>
        </inertia>
      </inertial>
      <velocity_decay>
        <linear>0</linear>
        <angular>0</angular>
      </velocity_decay>
    </link>
    <joint name='l_shoulder_yaw' type='revolute'>
      <child>l_upper_arm</child>
      <parent>l_shoulder_2</parent>
      <axis>
        <xyz>-6.5209e-06 2.59738e-06 -1</xyz>
        <limit>
          <lower>-0.645772</lower>
          <upper>1.74533</upper>
          <effort>34</effort>
          <velocity>100</velocity>
        </limit>
        <dynamics/>
      </axis>
    </joint>
    <link name='l_arm'>
      <pose>-0.0257497 -0.11026 0.0230202 1.57079 -6.5209e-06 -3.14159</pose>
      <inertial>
        <pose>-0.000156 0.05448 -9.87e-05 0 -0 0</pose>
        <mass>0.727843</mass>
        <inertia>
          <ixx>0.01</ixx>
          <ixy>2.29e-06</ixy>
          <ixz>-1.08e-06</ixz>
          <iyy>0.01</iyy>
          <iyz>-3.57e-06</iyz>
          <izz>0.01</izz>
        </inertia>
      </inertial>
      <collision name='l_arm_collision'>
        <pose>-0.0204334 0.15228 0.000143922 1.5708 1.309 1.90457e-11</pose>
        <geometry>
          <mesh>
            <scale>1 1 1</scale>
            <uri>model://iCubGenova01/meshes/collision/icub_simple_collision_l_arm.dae</uri>
          </mesh>
        </geometry>
      </collision>
      <visual name='l_arm_visual'>
        <pose>-0.0204334 0.15228 0.000143922 1.5708 1.309 1.90457e-11</pose>
        <geometry>
          <mesh>
            <scale>1 1 1</scale>
            <uri>model://iCubGenova01/meshes/visual/icub_l_arm.dae</uri>
          </mesh>
        </geometry>
      </visual>
      <velocity_decay>
        <linear>0</linear>
        <angular>0</angular>
      </velocity_decay>
    </link>
    <joint name='l_arm_ft_sensor' type='revolute'>
      <child>l_arm</child>
      <parent>l_upper_arm</parent>
      <axis>
        <xyz>0 0 0</xyz>
        <limit>
          <lower>0</lower>
          <upper>0</upper>
          <effort>0</effort>
          <velocity>0</velocity>
        </limit>
        <dynamics/>
      </axis>
      <sensor name='left_arm_ft' type='force_torque'>
        <always_on>1</always_on>
        <update_rate>100</update_rate>
        <pose>0 0 0 0 0 0</pose>
        <plugin name='left_arm_ft_plugin' filename='libgazebo_yarp_forcetorque.so'>
          <yarpConfigurationFile>model://iCubGenova01/conf/FT/gazebo_icub_left_arm_ft.ini</yarpConfigurationFile>
        </plugin>
      </sensor>
    </joint>
    <link name='l_elbow_1'>
      <pose>-0.0257497 -0.11026 0.0230202 3.14159 -6.5209e-06 -3.14159</pose>
      <inertial>
        <pose>-0.0013 0.00371 -0.00105 0 -0 0</pose>
        <mass>0.1</mass>
        <inertia>
          <ixx>0.01</ixx>
          <ixy>-5.15e-07</ixy>
          <ixz>-4.08e-07</ixz>
          <iyy>0.01</iyy>
          <iyz>-3.71e-07</iyz>
          <izz>0.01</izz>
        </inertia>
      </inertial>
      <velocity_decay>
        <linear>0</linear>
        <angular>0</angular>
      </velocity_decay>
    </link>
    <joint name='l_elbow' type='revolute'>
      <child>l_elbow_1</child>
      <parent>l_arm</parent>
      <axis>
        <xyz>-1.01957e-06 1 2.59739e-06</xyz>
        <limit>
          <lower>0.0959931</lower>
          <upper>1.85005</upper>
          <effort>20</effort>
          <velocity>100</velocity>
        </limit>
        <dynamics/>
      </axis>
    </joint>
    <link name='l_forearm'>
      <pose>-0.0107497 -0.11026 0.0230201 -1.5708 2.59741e-06 -1.57079</pose>
      <inertial>
        <pose>0.000347 0.066 0.00476 0 -0 0</pose>
        <mass>0.525</mass>
        <inertia>
          <ixx>0.01</ixx>
          <ixy>4.337e-06</ixy>
          <ixz>2.39e-07</ixz>
          <iyy>0.01</iyy>
          <iyz>1.9381e-05</iyz>
          <izz>0.01</izz>
        </inertia>
      </inertial>
      <collision name='l_forearm_collision'>
        <pose>-0.000143922 -1.25974e-12 0.0204334 -2.66395 1.57079 -1.09315</pose>
        <geometry>
          <mesh>
            <scale>1 1 1</scale>
            <uri>model://iCubGenova01/meshes/collision/icub_simple_collision_l_forearm.dae</uri>
          </mesh>
        </geometry>
      </collision>
      <visual name='l_forearm_visual'>
        <pose>-0.000143922 -1.25974e-12 0.0204334 -2.66395 1.57079 -1.09315</pose>
        <geometry>
          <mesh>
            <scale>1 1 1</scale>
            <uri>model://iCubGenova01/meshes/visual/icub_l_forearm.dae</uri>
          </mesh>
        </geometry>
      </visual>
      <velocity_decay>
        <linear>0</linear>
        <angular>0</angular>
      </velocity_decay>
    </link>
    <joint name='l_wrist_prosup' type='revolute'>
      <child>l_forearm</child>
      <parent>l_elbow_1</parent>
      <axis>
        <xyz>-2.8477e-06 2.5974e-06 -1</xyz>
        <limit>
          <lower>-0.872665</lower>
          <upper>0.872665</upper>
          <effort>0.45</effort>
          <velocity>100</velocity>
        </limit>
        <dynamics/>
      </axis>
    </joint>
    <link name='l_wrist_1'>
      <pose>-0.0107501 -0.110259 -0.11428 -2.7153 1.57079 1.99709</pose>
      <inertial>
        <pose>0 0 0 0 -0 0</pose>
        <mass>0.1</mass>
        <inertia>
          <ixx>0.01</ixx>
          <ixy>0</ixy>
          <ixz>0</ixz>
          <iyy>0.01</iyy>
          <iyz>0</iyz>
          <izz>0.01</izz>
        </inertia>
      </inertial>
      <velocity_decay>
        <linear>0</linear>
        <angular>0</angular>
      </velocity_decay>
    </link>
    <joint name='l_wrist_pitch' type='revolute'>
      <child>l_wrist_1</child>
      <parent>l_forearm</parent>
      <axis>
        <xyz>1 1.01958e-06 -2.84771e-06</xyz>
        <limit>
          <lower>-1.13446</lower>
          <upper>0.174533</upper>
          <effort>0.65</effort>
          <velocity>100</velocity>
        </limit>
        <dynamics/>
      </axis>
    </joint>
    <link name='l_hand'>
      <pose>-0.0107501 -0.110259 -0.11428 -2.7153 1.57079 1.99709</pose>
      <inertial>
        <pose>0.07023 -0.00805 -0.007 0 -0 0</pose>
        <mass>0.213</mass>
        <inertia>
          <ixx>0.01</ixx>
          <ixy>1.278e-05</ixy>
          <ixz>4.823e-06</ixz>
          <iyy>0.01</iyy>
          <iyz>-1.8188e-05</iyz>
          <izz>0.01</izz>
        </inertia>
      </inertial>
      <collision name='l_hand_collision'>
        <pose>-1.25974e-12 0.0204334 -0.000143922 5.10271e-12 -2.6418e-12 1.49622e-11</pose>
        <geometry>
          <mesh>
            <scale>1 1 1</scale>
            <uri>model://iCubGenova01/meshes/collision/icub_simple_collision_l_hand.dae</uri>
          </mesh>
        </geometry>
      </collision>
      <visual name='l_hand_visual'>
        <pose>-1.25974e-12 0.0204334 -0.000143922 5.10271e-12 -2.6418e-12 1.49622e-11</pose>
        <geometry>
          <mesh>
            <scale>1 1 1</scale>
            <uri>model://iCubGenova01/meshes/visual/icub_l_hand.dae</uri>
          </mesh>
        </geometry>
      </visual>
      <velocity_decay>
        <linear>0</linear>
        <angular>0</angular>
      </velocity_decay>
    </link>
    <joint name='l_wrist_yaw' type='revolute'>
      <child>l_hand</child>
      <parent>l_wrist_1</parent>
      <axis>
        <xyz>1.01956e-06 -1 -6.27061e-06</xyz>
        <limit>
          <lower>-0.436332</lower>
          <upper>0.436332</upper>
          <effort>0.65</effort>
          <velocity>100</velocity>
        </limit>
        <dynamics/>
      </axis>
    </joint>
    <link name='neck_1'>
      <pose>-0.00780846 1.22355e-08 0.2253 6.12199e-06 -1.57079 -1.42918e-06</pose>
      <inertial>
        <pose>0 0 0 0 -0 0</pose>
        <mass>0.1</mass>
        <inertia>
          <ixx>0.01</ixx>
          <ixy>0</ixy>
          <ixz>0</ixz>
          <iyy>0.01</iyy>
          <iyz>0</iyz>
          <izz>0.01</izz>
        </inertia>
      </inertial>
      <collision name='neck_1_collision'>
        <pose>-5.55112e-17 9.62889e-13 -0.0055 3.14159 -1.57079 1.5708</pose>
        <geometry>
          <mesh>
            <scale>1 1 1</scale>
            <uri>model://iCubGenova01/meshes/collision/icub_simple_collision_neck_1.dae</uri>
          </mesh>
        </geometry>
      </collision>
      <visual name='neck_1_visual'>
        <pose>-5.55112e-17 9.62889e-13 -0.0055 3.14159 -1.57079 1.5708</pose>
        <geometry>
          <mesh>
            <scale>1 1 1</scale>
            <uri>model://iCubGenova01/meshes/visual/icub_neck_1.dae</uri>
          </mesh>
        </geometry>
      </visual>
      <velocity_decay>
        <linear>0</linear>
        <angular>0</angular>
      </velocity_decay>
    </link>
    <joint name='neck_pitch' type='revolute'>
      <child>neck_1</child>
      <parent>chest</parent>
      <axis>
        <xyz>-4.69281e-06 1 6.74621e-11</xyz>
        <limit>
          <lower>-0.698132</lower>
          <upper>0.523599</upper>
          <effort>20</effort>
          <velocity>100</velocity>
        </limit>
        <dynamics/>
      </axis>
    </joint>
    <link name='neck_2'>
      <pose>-0.00780836 1.22353e-08 0.2348 -1.46928e-05 3.67327e-06 -1.57079</pose>
      <inertial>
        <pose>0 0 0 0 -0 0</pose>
        <mass>0.1</mass>
        <inertia>
          <ixx>0.01</ixx>
          <ixy>0</ixy>
          <ixz>0</ixz>
          <iyy>0.01</iyy>
          <iyz>0</iyz>
          <izz>0.01</izz>
        </inertia>
      </inertial>
      <collision name='neck_2_collision'>
        <pose>-9.62885e-13 0.0055 0.0235 -3.14157 -1.57079 -1.57082</pose>
        <geometry>
          <mesh>
            <scale>1 1 1</scale>
            <uri>model://iCubGenova01/meshes/collision/icub_simple_collision_neck_2.dae</uri>
          </mesh>
        </geometry>
      </collision>
      <visual name='neck_2_visual'>
        <pose>-9.62885e-13 0.0055 0.0235 -3.14157 -1.57079 -1.57082</pose>
        <geometry>
          <mesh>
            <scale>1 1 1</scale>
            <uri>model://iCubGenova01/meshes/visual/icub_neck_2.dae</uri>
          </mesh>
        </geometry>
      </visual>
      <velocity_decay>
        <linear>0</linear>
        <angular>0</angular>
      </velocity_decay>
    </link>
    <joint name='neck_roll' type='revolute'>
      <child>neck_2</child>
      <parent>neck_1</parent>
      <axis>
        <xyz>-1 -4.69282e-06 1.46928e-05</xyz>
        <limit>
          <lower>-1.22173</lower>
          <upper>1.0472</upper>
          <effort>20</effort>
          <velocity>100</velocity>
        </limit>
        <dynamics/>
      </axis>
    </joint>
    <link name='head'>
      <pose>-0.00780836 1.22353e-08 0.2348 -1.5708 1.46928e-05 8.36603e-06</pose>
      <inertial>
        <pose>0.0185 -0.1108 6.78454e-18 0 -0 0</pose>
        <mass>1.33687</mass>
        <inertia>
          <ixx>0.01</ixx>
          <ixy>0</ixy>
          <ixz>2.40741e-35</ixz>
          <iyy>0.01</iyy>
          <iyz>0</iyz>
          <izz>0.01</izz>
        </inertia>
      </inertial>
      <collision name='head_collision'>
        <pose>0.0045 -0.0235 9.42472e-13 -1.32582 1.57079 -2.89662</pose>
        <geometry>
          <mesh>
            <scale>1 1 1</scale>
            <uri>model://iCubGenova01/meshes/collision/icub_simple_collision_head.dae</uri>
          </mesh>
        </geometry>
      </collision>
      <visual name='head_visual'>
        <pose>0.0045 -0.0235 9.42472e-13 -1.32582 1.57079 -2.89662</pose>
        <geometry>
          <mesh>
            <scale>1 1 1</scale>
            <uri>model://iCubGenova01/meshes/visual/icub_head.dae</uri>
          </mesh>
        </geometry>
      </visual>
      <velocity_decay>
        <linear>0</linear>
        <angular>0</angular>
      </velocity_decay>
      <sensor name='imu_sensor' type='imu'>
        <always_on>1</always_on>
        <update_rate>100</update_rate>
        <visualize>1</visualize>
        <imu/>
        <plugin name='iCub_yarp_gazebo_plugin_IMU' filename='libgazebo_yarp_imu.so'>
          <yarpConfigurationFile>model://iCubGenova01/conf/gazebo_icub_inertial.ini</yarpConfigurationFile>
        </plugin>
        <pose>0.0185 -0.1108 0.0066 1.5708 -0 0</pose>
      </sensor>
    </link>
    <joint name='neck_yaw' type='revolute'>
      <child>head</child>
      <parent>neck_2</parent>
      <axis>
        <xyz>1.46928e-05 1.48834e-12 1</xyz>
        <limit>
          <lower>-0.959931</lower>
          <upper>0.959931</upper>
          <effort>20</effort>
          <velocity>100</velocity>
        </limit>
        <dynamics/>
      </axis>
    </joint>
    <link name='r_shoulder_1'>
      <pose>-0.0107489 0.11026 0.1753 -2.87979 -1.57079 -1.42916e-06</pose>
      <inertial>
        <pose>5e-06 0.0187 0.00119 0 -0 0</pose>
        <mass>0.189</mass>
        <inertia>
          <ixx>0.01</ixx>
          <ixy>2.1e-08</ixy>
          <ixz>-1e-09</ixz>
          <iyy>0.01</iyy>
          <iyz>4.22e-06</iyz>
          <izz>0.01</izz>
        </inertia>
      </inertial>
      <collision name='r_shoulder_1_collision'>
        <pose>-3.08642e-14 0.109285 0.00521101 3.06003 1.57079 -1.65235</pose>
        <geometry>
          <mesh>
            <scale>1 1 1</scale>
            <uri>model://iCubGenova01/meshes/collision/icub_simple_collision_r_shoulder_1.dae</uri>
          </mesh>
        </geometry>
      </collision>
      <visual name='r_shoulder_1_visual'>
        <pose>-3.08642e-14 0.109285 0.00521101 3.06003 1.57079 -1.65235</pose>
        <geometry>
          <mesh>
            <scale>1 1 1</scale>
            <uri>model://iCubGenova01/meshes/visual/icub_r_shoulder_1.dae</uri>
          </mesh>
        </geometry>
      </visual>
      <velocity_decay>
        <linear>0</linear>
        <angular>0</angular>
      </velocity_decay>
    </link>
    <joint name='r_shoulder_pitch' type='revolute'>
      <child>r_shoulder_1</child>
      <parent>chest</parent>
      <axis>
        <xyz>0.258817 -0.965926 -2.85208e-06</xyz>
        <limit>
          <lower>-1.65806</lower>
          <upper>0.0872665</upper>
          <effort>84</effort>
          <velocity>100</velocity>
        </limit>
        <dynamics/>
      </axis>
    </joint>
    <link name='r_shoulder_2'>
      <pose>-0.0107489 0.11026 0.1753 6.97094e-06 8.21122e-07 1.83259</pose>
      <inertial>
        <pose>-9.4e-05 -0.00627 -0.0166 0 -0 0</pose>
        <mass>0.179</mass>
        <inertia>
          <ixx>0.01</ixx>
          <ixy>-4.53e-07</ixy>
          <ixz>2.03e-07</ixz>
          <iyy>0.01</iyy>
          <iyz>2.07e-05</iyz>
          <izz>0.01</izz>
        </inertia>
      </inertial>
      <collision name='r_shoulder_2_collision'>
        <pose>-0.00154529 -0.00521101 -1.11181e-12 -1.00125 -1.57079 2.57205</pose>
        <geometry>
          <mesh>
            <scale>1 1 1</scale>
            <uri>model://iCubGenova01/meshes/collision/icub_simple_collision_r_shoulder_2.dae</uri>
          </mesh>
        </geometry>
      </collision>
      <visual name='r_shoulder_2_visual'>
        <pose>-0.00154529 -0.00521101 -1.11181e-12 -1.00125 -1.57079 2.57205</pose>
        <geometry>
          <mesh>
            <scale>1 1 1</scale>
            <uri>model://iCubGenova01/meshes/visual/icub_r_shoulder_2.dae</uri>
          </mesh>
        </geometry>
      </visual>
      <velocity_decay>
        <linear>0</linear>
        <angular>0</angular>
      </velocity_decay>
    </link>
    <joint name='r_shoulder_roll' type='revolute'>
      <child>r_shoulder_2</child>
      <parent>r_shoulder_1</parent>
      <axis>
        <xyz>0.965926 0.258817 -6.97094e-06</xyz>
        <limit>
          <lower>0</lower>
          <upper>2.80649</upper>
          <effort>84</effort>
          <velocity>100</velocity>
        </limit>
        <dynamics/>
      </axis>
    </joint>
    <link name='r_upper_arm'>
      <pose>-0.0107489 0.11026 0.1753 3.14159 -6.5209e-06 -3.14159</pose>
      <inertial>
        <pose>0.00553932 -2.47652e-05 0.0493895 0 -0 0</pose>
        <mass>0.155</mass>
        <inertia>
          <ixx>0.01</ixx>
          <ixy>3.56977e-07</ixy>
          <ixz>-3.95372e-06</ixz>
          <iyy>0.01</iyy>
          <iyz>-6.5128e-06</iyz>
          <izz>0.01</izz>
        </inertia>
      </inertial>
      <velocity_decay>
        <linear>0</linear>
        <angular>0</angular>
      </velocity_decay>
    </link>
    <joint name='r_shoulder_yaw' type='revolute'>
      <child>r_upper_arm</child>
      <parent>r_shoulder_2</parent>
      <axis>
        <xyz>6.5209e-06 -5.62481e-08 1</xyz>
        <limit>
          <lower>-0.645772</lower>
          <upper>1.74533</upper>
          <effort>34</effort>
          <velocity>100</velocity>
        </limit>
        <dynamics/>
      </axis>
    </joint>
    <link name='r_arm'>
      <pose>-0.0257499 0.11026 0.0230202 -1.57079 6.5209e-06 3.6732e-06</pose>
      <inertial>
        <pose>0.00015906 -0.0543972 8.28733e-05 0 -0 0</pose>
        <mass>0.729</mass>
        <inertia>
          <ixx>0.01</ixx>
          <ixy>2.29e-06</ixy>
          <ixz>1.08e-06</ixz>
          <iyy>0.01</iyy>
          <iyz>3.57e-06</iyz>
          <izz>0.01</izz>
        </inertia>
      </inertial>
      <collision name='r_arm_collision'>
        <pose>0.0204334 -0.15228 -0.000143922 -1.5708 -1.309 3.14159</pose>
        <geometry>
          <mesh>
            <scale>1 1 1</scale>
            <uri>model://iCubGenova01/meshes/collision/icub_simple_collision_r_arm.dae</uri>
          </mesh>
        </geometry>
      </collision>
      <visual name='r_arm_visual'>
        <pose>0.0204334 -0.15228 -0.000143922 -1.5708 -1.309 3.14159</pose>
        <geometry>
          <mesh>
            <scale>1 1 1</scale>
            <uri>model://iCubGenova01/meshes/visual/icub_r_arm.dae</uri>
          </mesh>
        </geometry>
      </visual>
      <velocity_decay>
        <linear>0</linear>
        <angular>0</angular>
      </velocity_decay>
    </link>
    <joint name='r_arm_ft_sensor' type='revolute'>
      <child>r_arm</child>
      <parent>r_upper_arm</parent>
      <axis>
        <xyz>0 -0 0</xyz>
        <limit>
          <lower>0</lower>
          <upper>0</upper>
          <effort>0</effort>
          <velocity>0</velocity>
        </limit>
        <dynamics/>
      </axis>
      <sensor name='right_arm_ft' type='force_torque'>
        <always_on>1</always_on>
        <update_rate>100</update_rate>
        <pose>0 0 0 0 0 0</pose>
        <plugin name='right_arm_ft_plugin' filename='libgazebo_yarp_forcetorque.so'>
          <yarpConfigurationFile>model://iCubGenova01/conf/FT/gazebo_icub_right_arm_ft.ini</yarpConfigurationFile>
        </plugin>
      </sensor>
    </joint>
    <link name='r_elbow_1'>
      <pose>-0.0257499 0.11026 0.0230202 7.40268e-06 6.5209e-06 3.6732e-06</pose>
      <inertial>
        <pose>0.0013 -0.00371 0.00105 0 -0 0</pose>
        <mass>0.1</mass>
        <inertia>
          <ixx>0.01</ixx>
          <ixy>-5.02e-07</ixy>
          <ixz>-3.99e-07</ixz>
          <iyy>0.01</iyy>
          <iyz>-3.71e-07</iyz>
          <izz>0.01</izz>
        </inertia>
      </inertial>
      <velocity_decay>
        <linear>0</linear>
        <angular>0</angular>
      </velocity_decay>
    </link>
    <joint name='r_elbow' type='revolute'>
      <child>r_elbow_1</child>
      <parent>r_arm</parent>
      <axis>
        <xyz>-3.67316e-06 1 7.40268e-06</xyz>
        <limit>
          <lower>0.0959931</lower>
          <upper>1.85005</upper>
          <effort>20</effort>
          <velocity>100</velocity>
        </limit>
        <dynamics/>
      </axis>
    </joint>
    <link name='r_forearm'>
      <pose>-0.0107499 0.11026 0.0230201 1.57079 7.40266e-06 -1.5708</pose>
      <inertial>
        <pose>-0.000347 -0.066 -0.00476 0 -0 0</pose>
        <mass>0.525</mass>
        <inertia>
          <ixx>0.01</ixx>
          <ixy>5.66e-06</ixy>
          <ixz>1.4e-06</ixz>
          <iyy>0.01</iyy>
          <iyz>1.82e-05</iyz>
          <izz>0.01</izz>
        </inertia>
      </inertial>
      <collision name='r_forearm_collision'>
        <pose>0.000143922 -1.07213e-12 -0.0204334 -1.74166 1.57079 -0.170863</pose>
        <geometry>
          <mesh>
            <scale>1 1 1</scale>
            <uri>model://iCubGenova01/meshes/collision/icub_simple_collision_r_forearm.dae</uri>
          </mesh>
        </geometry>
      </collision>
      <visual name='r_forearm_visual'>
        <pose>0.000143922 -1.07213e-12 -0.0204334 -1.74166 1.57079 -0.170863</pose>
        <geometry>
          <mesh>
            <scale>1 1 1</scale>
            <uri>model://iCubGenova01/meshes/visual/icub_r_forearm.dae</uri>
          </mesh>
        </geometry>
      </visual>
      <velocity_decay>
        <linear>0</linear>
        <angular>0</angular>
      </velocity_decay>
    </link>
    <joint name='r_wrist_prosup' type='revolute'>
      <child>r_forearm</child>
      <parent>r_elbow_1</parent>
      <axis>
        <xyz>2.84772e-06 -7.40266e-06 1</xyz>
        <limit>
          <lower>-0.872665</lower>
          <upper>0.872665</upper>
          <effort>0.45</effort>
          <velocity>100</velocity>
        </limit>
        <dynamics/>
      </axis>
    </joint>
    <link name='r_wrist_1'>
      <pose>-0.0107503 0.110261 -0.11428 2.48946 -1.57079 -0.918663</pose>
      <inertial>
        <pose>0 0 0 0 -0 0</pose>
        <mass>0.1</mass>
        <inertia>
          <ixx>0.01</ixx>
          <ixy>0</ixy>
          <ixz>0</ixz>
          <iyy>0.01</iyy>
          <iyz>0</iyz>
          <izz>0.01</izz>
        </inertia>
      </inertial>
      <velocity_decay>
        <linear>0</linear>
        <angular>0</angular>
      </velocity_decay>
    </link>
    <joint name='r_wrist_pitch' type='revolute'>
      <child>r_wrist_1</child>
      <parent>r_forearm</parent>
      <axis>
        <xyz>-1 -3.67318e-06 2.84771e-06</xyz>
        <limit>
          <lower>-1.13446</lower>
          <upper>0.174533</upper>
          <effort>0.65</effort>
          <velocity>100</velocity>
        </limit>
        <dynamics/>
      </axis>
    </joint>
    <link name='r_hand'>
      <pose>-0.0107503 0.110261 -0.11428 -2.16655 1.57079 2.54584</pose>
      <inertial>
        <pose>0.07023 -0.00805 0.007 0 -0 0</pose>
        <mass>0.213</mass>
        <inertia>
          <ixx>0.01</ixx>
          <ixy>1.26e-05</ixy>
          <ixz>-6.08e-06</ixz>
          <iyy>0.01</iyy>
          <iyz>1.76e-05</iyz>
          <izz>0.01</izz>
        </inertia>
      </inertial>
      <collision name='r_hand_collision'>
        <pose>1.0721e-12 0.0204334 0.000143922 1.53098e-11 2.00653e-11 -3.14159</pose>
        <geometry>
          <mesh>
            <scale>1 1 1</scale>
            <uri>model://iCubGenova01/meshes/collision/icub_simple_collision_r_hand.dae</uri>
          </mesh>
        </geometry>
      </collision>
      <visual name='r_hand_visual'>
        <pose>1.0721e-12 0.0204334 0.000143922 1.53098e-11 2.00653e-11 -3.14159</pose>
        <geometry>
          <mesh>
            <scale>1 1 1</scale>
            <uri>model://iCubGenova01/meshes/visual/icub_r_hand.dae</uri>
          </mesh>
        </geometry>
      </visual>
      <velocity_decay>
        <linear>0</linear>
        <angular>0</angular>
      </velocity_decay>
    </link>
    <joint name='r_wrist_yaw' type='revolute'>
      <child>r_hand</child>
      <parent>r_wrist_1</parent>
      <axis>
        <xyz>3.67317e-06 -1 -3.72946e-06</xyz>
        <limit>
          <lower>-0.436332</lower>
          <upper>0.436332</upper>
          <effort>0.65</effort>
          <velocity>100</velocity>
        </limit>
        <dynamics/>
      </axis>
    </joint>
    <plugin name='controlboard_torso' filename='libgazebo_yarp_controlboard.so'>
      <yarpConfigurationFile>model://iCubGenova01/conf/gazebo_icub_torso.ini</yarpConfigurationFile>
    </plugin>
    <plugin name='controlboard_head' filename='libgazebo_yarp_controlboard.so'>
      <yarpConfigurationFile>model://iCubGenova01/conf/gazebo_icub_head.ini</yarpConfigurationFile>
    </plugin>
    <plugin name='controlboard_left_arm' filename='libgazebo_yarp_controlboard.so'>
      <yarpConfigurationFile>model://iCubGenova01/conf/gazebo_icub_left_arm.ini</yarpConfigurationFile>
      <initialConfiguration>-0.52 0.52 0 0.785 0 0 0.698</initialConfiguration>
    </plugin>
    <plugin name='controlboard_right_arm' filename='libgazebo_yarp_controlboard.so'>
      <yarpConfigurationFile>model://iCubGenova01/conf/gazebo_icub_right_arm.ini</yarpConfigurationFile>
      <initialConfiguration>-0.52 0.52 0 0.785 0 0 0.698</initialConfiguration>
    </plugin>
    <plugin name='controlboard_left_leg' filename='libgazebo_yarp_controlboard.so'>
      <yarpConfigurationFile>model://iCubGenova01/conf/gazebo_icub_left_leg.ini</yarpConfigurationFile>
    </plugin>
    <plugin name='controlboard_right_leg' filename='libgazebo_yarp_controlboard.so'>
      <yarpConfigurationFile>model://iCubGenova01/conf/gazebo_icub_right_leg.ini</yarpConfigurationFile>
    </plugin>
    <pose>0 0 0.70 0 0 0</pose>
  </model>
</sdf>
